Workbook

Sheet Brownian Motion simulation
A1: GEOMETRIC BROWNIAN MOTION
A2: Initial Price | B2: 22828 | E2: Press F9 to generate new Zs
A3: Expected Return | B3: 0.08
A4: Annual Volatility | B4: 0.1939
A5: Time (In years) | B5: 1
A6: Steps per year (N) | B6: 252
A7: Delta | B7: =B5/B6 -> 0.003968254
A9: Step | B9: Random Z | C9: Simulated Price
A10: 0 | C10: =B2 -> 22828
A11: =A10+1 -> 1 | B11: =_xlfn.NORM.S.INV(RAND()) -> 0.22234656 | C11: =C10 * EXP((($B$3 - 0.5 * $B$4^2) * $B$7) + ($B$4 * SQRT($B$7) * B11)) -> 22895.642
A12: =A11+1 -> 2 | B12: =_xlfn.NORM.S.INV(RAND()) -> -0.055258016 | C12: =C11 * EXP((($B$3 - 0.5 * $B$4^2) * $B$7) + ($B$4 * SQRT($B$7) * B12)) -> 22885.751
A13: =A12+1 -> 3 | B13: =_xlfn.NORM.S.INV(RAND()) -> 0.72289923 | C13: =C12 * EXP((($B$3 - 0.5 * $B$4^2) * $B$7) + ($B$4 * SQRT($B$7) * B13)) -> 23094.333
A14: =A13+1 -> 4 | B14: =_xlfn.NORM.S.INV(RAND()) -> 0.18127595 | C14: =C13 * EXP((($B$3 - 0.5 * $B$4^2) * $B$7) + ($B$4 * SQRT($B$7) * B14)) -> 23151.147
A15: =A14+1 -> 5 | B15: =_xlfn.NORM.S.INV(RAND()) -> 0.32107224 | C15: =C14 * EXP((($B$3 - 0.5 * $B$4^2) * $B$7) + ($B$4 * SQRT($B$7) * B15)) -> 23247.763
A16: =A15+1 -> 6 | B16: =_xlfn.NORM.S.INV(RAND()) -> -1.1493093 | C16: =C15 * EXP((($B$3 - 0.5 * $B$4^2) * $B$7) + ($B$4 * SQRT($B$7) * B16)) -> 22929.252
A17: =A16+1 -> 7 | B17: =_xlfn.NORM.S.INV(RAND()) -> 0.19794035 | C17: =C16 * EXP((($B$3 - 0.5 * $B$4^2) * $B$7) + ($B$4 * SQRT($B$7) * B17)) -> 22990.339
A18: =A17+1 -> 8 | B18: =_xlfn.NORM.S.INV(RAND()) -> -0.22758303 | C18: =C17 * EXP((($B$3 - 0.5 * $B$4^2) * $B$7) + ($B$4 * SQRT($B$7) * B18)) -> 22932.088
A19: =A18+1 -> 9 | B19: =_xlfn.NORM.S.INV(RAND()) -> -0.14305628 | C19: =C18 * EXP((($B$3 - 0.5 * $B$4^2) * $B$7) + ($B$4 * SQRT($B$7) * B19)) -> 22897.612
A20: =A19+1 -> 10 | B20: =_xlfn.NORM.S.INV(RAND()) -> 1.4851243 | C20: =C19 * EXP((($B$3 - 0.5 * $B$4^2) * $B$7) + ($B$4 * SQRT($B$7) * B20)) -> 23322.432
A21: =A20+1 -> 11 | B21: =_xlfn.NORM.S.INV(RAND()) -> -0.59524732 | C21: =C20 * EXP((($B$3 - 0.5 * $B$4^2) * $B$7) + ($B$4 * SQRT($B$7) * B21)) -> 23159.1
A22: =A21+1 -> 12 | B22: =_xlfn.NORM.S.INV(RAND()) -> -1.0507203 | C22: =C21 * EXP((($B$3 - 0.5 * $B$4^2) * $B$7) + ($B$4 * SQRT($B$7) * B22)) -> 22869.327
... A262: =A261+1 -> 252 | B262: =_xlfn.NORM.S.INV(RAND()) -> -1.4154789 | C262: =C261 * EXP((($B$3 - 0.5 * $B$4^2) * $B$7) + ($B$4 * SQRT($B$7) * B262)) -> 22224.614

Sheet Black-Scholes
A2: Current Price (S) | B2: 22828 | D2: Metric | E2: Call | F2: Put
A3: Strike Price (K) | B3: 22900 | D3: Delta | E3: =_xlfn.NORM.S.DIST(B8, TRUE) -> 0.48743359 | F3: =_xlfn.NORM.S.DIST(B8, TRUE) - 1 -> -0.51256641
A4: Time to Maturity (T) | B4: 0.02466 | D4: Gamma | E4: =_xlfn.NORM.S.DIST(B8,FALSE)/(B2*B5*SQRT(B4)) -> 0.00057365704 | F4: =_xlfn.NORM.S.DIST(B8,FALSE)/(B2*B5*SQRT(B4)) -> 0.00057365704
A5: Volatility (Sigma) | B5: 0.1939 | D5: Theta | E5: =-(B2 * _xlfn.NORM.S.DIST(B8,FALSE) * B5) / (2 * SQRT(B4)) - B6 * B3 * EXP(-B6 * B4) * _xlfn.NORM.S.DIST(B9,TRUE) -> -6380.2987 | F5: =-(B2 * _xlfn.NORM.S.DIST(B8,FALSE) * B5) / (2 * SQRT(B4)) + B6 * B3 * EXP(-B6 * B4) * _xlfn.NORM.S.DIST(-B9,TRUE) -> -4780.0635
A6: Risk-free Rate (r) | B6: 0.07 | D6: Vega | E6: =B2 * _xlfn.NORM.S.DIST(B8,FALSE) * SQRT(B4) -> 1429.417 | F6: =B2 * _xlfn.NORM.S.DIST(B8,FALSE) * SQRT(B4) -> 1429.417
D7: Rho | E7: =B3 * B4 * EXP(-B6 * B4) * _xlfn.NORM.S.DIST(B9,TRUE) -> 267.94557 | F7: =-B3 * B4 * EXP(-B6 * B4) * _xlfn.NORM.S.DIST(-B9,TRUE) -> -295.79446
A8: d1 | B8: =(LN(B2/B3)+(B6+0.5*B5^2)*B4)/(B5*SQRT(B4)) -> -0.031504529
A9: d2 | B9: =B8 - B5*SQRT(B4) -> -0.06195362
A10: Call Price (C) | B10: =B2*_xlfn.NORM.S.DIST(B8,TRUE) - B3*EXP(-B6*B4)*_xlfn.NORM.S.DIST(B9,TRUE) -> 261.53906
A11: Put Price (P) | B11: =B3*EXP(-B6*B4)*_xlfn.NORM.S.DIST(-B9,TRUE) - B2*_xlfn.NORM.S.DIST(-B8,TRUE) -> 294.04318

Sheet Normal Distribution
D1: PRICE RANGE | E1: PDF VALUES
A2: Spot Price (S) | B2: 22828 | D2: =B2*EXP(-4*B5) -> 20210.282 | E2: =_xlfn.NORM.DIST(LN(D2/$B$2), 0, $B$5, FALSE)/D2 -> 2.1747407e-07
A3: Volatility (Sigma) | B3: 0.1939 | D3: =$D2*EXP(0.2*$B$5) -> 20333.734 | E3: =_xlfn.NORM.DIST(LN(D3/$B$2), 0, $B$5, FALSE)/D3 -> 4.7153335e-07
A4: Time to expiry (T) in years | B4: 0.02466 | D4: =$D3*EXP(0.2*$B$5) -> 20457.941 | E4: =_xlfn.NORM.DIST(LN(D4/$B$2), 0, $B$5, FALSE)/D4 -> 9.8230319e-07
A5: Std Dev of Log Returns | B5: =B3 * SQRT(B4) -> 0.030449092 | D5: =$D4*EXP(0.2*$B$5) -> 20582.906 | E5: =_xlfn.NORM.DIST(LN(D5/$B$2), 0, $B$5, FALSE)/D5 -> 1.966106e-06
D6: =$D5*EXP(0.2*$B$5) -> 20708.635 | E6: =_xlfn.NORM.DIST(LN(D6/$B$2), 0, $B$5, FALSE)/D6 -> 3.7809114e-06
A7: EXPECTED PRICE RANGE AT EXPIRY | D7: =$D6*EXP(0.2*$B$5) -> 20835.132 | E7: =_xlfn.NORM.DIST(LN(D7/$B$2), 0, $B$5, FALSE)/D7 -> 6.9857704e-06
A8: 1σ Upper | B8: =B2*EXP(B5) -> 23533.783 | D8: =$D7*EXP(0.2*$B$5) -> 20962.401 | E8: =_xlfn.NORM.DIST(LN(D8/$B$2), 0, $B$5, FALSE)/D8 -> 1.2401103e-05
A9: 1σ Lower | B9: =B2*EXP(-B5) -> 22143.384 | D9: =$D8*EXP(0.2*$B$5) -> 21090.448 | E9: =_xlfn.NORM.DIST(LN(D9/$B$2), 0, $B$5, FALSE)/D9 -> 2.1151179e-05
A10: 2σ Upper | B10: =B2*EXP(2*B5) -> 24261.386 | D10: =$D9*EXP(0.2*$B$5) -> 21219.276 | E10: =_xlfn.NORM.DIST(LN(D10/$B$2), 0, $B$5, FALSE)/D10 -> 3.4660677e-05
A11: 2σ Lower | B11: =B2*EXP(-2*B5) -> 21479.3 | D11: =$D10*EXP(0.2*$B$5) -> 21348.892 | E11: =_xlfn.NORM.DIST(LN(D11/$B$2), 0, $B$5, FALSE)/D11 -> 5.4571731e-05
A12: 3σ Upper | B12: =B2*EXP(3*B5) -> 25011.485 | D12: =$D11*EXP(0.2*$B$5) -> 21479.3 | E12: =_xlfn.NORM.DIST(LN(D12/$B$2), 0, $B$5, FALSE)/D12 -> 8.2551817e-05
A13: 3σ Lower | B13: =B2*EXP(-3*B5) -> 20835.132 | D13: =$D12*EXP(0.2*$B$5) -> 21610.504 | E13: =_xlfn.NORM.DIST(LN(D13/$B$2), 0, $B$5, FALSE)/D13 -> 0.00011998136
D14: =$D13*EXP(0.2*$B$5) -> 21742.509 | E14: =_xlfn.NORM.DIST(LN(D14/$B$2), 0, $B$5, FALSE)/D14 -> 0.00016754409
D15: =$D14*EXP(0.2*$B$5) -> 21875.321 | E15: =_xlfn.NORM.DIST(LN(D15/$B$2), 0, $B$5, FALSE)/D15 -> 0.00022478777
D16: =$D15*EXP(0.2*$B$5) -> 22008.945 | E16: =_xlfn.NORM.DIST(LN(D16/$B$2), 0, $B$5, FALSE)/D16 -> 0.00028976403
D17: =$D16*EXP(0.2*$B$5) -> 22143.384 | E17: =_xlfn.NORM.DIST(LN(D17/$B$2), 0, $B$5, FALSE)/D17 -> 0.00035887606
D18: =$D17*EXP(0.2*$B$5) -> 22278.645 | E18: =_xlfn.NORM.DIST(LN(D18/$B$2), 0, $B$5, FALSE)/D18 -> 0.00042704409
D19: =$D18*EXP(0.2*$B$5) -> 22414.731 | E19: =_xlfn.NORM.DIST(LN(D19/$B$2), 0, $B$5, FALSE)/D19 -> 0.0004882353
D20: =$D19*EXP(0.2*$B$5) -> 22551.65 | E20: =_xlfn.NORM.DIST(LN(D20/$B$2), 0, $B$5, FALSE)/D20 -> 0.00053630747 | O20: `
D21: =$D20*EXP(0.2*$B$5) -> 22689.404 | E21: =_xlfn.NORM.DIST(LN(D21/$B$2), 0, $B$5, FALSE)/D21 -> 0.00056601344
D22: =$D21*EXP(0.2*$B$5) -> 22828 | E22: =_xlfn.NORM.DIST(LN(D22/$B$2), 0, $B$5, FALSE)/D22 -> 0.0005739418
D23: =$D22*EXP(0.2*$B$5) -> 22967.443 | E23: =_xlfn.NORM.DIST(LN(D23/$B$2), 0, $B$5, FALSE)/D23 -> 0.00055916141
D24: =$D23*EXP(0.2*$B$5) -> 23107.737 | E24: =_xlfn.NORM.DIST(LN(D24/$B$2), 0, $B$5, FALSE)/D24 -> 0.00052340124
D25: =$D24*EXP(0.2*$B$5) -> 23248.888 | E25: =_xlfn.NORM.DIST(LN(D25/$B$2), 0, $B$5, FALSE)/D25 -> 0.0004707177
D26: =$D25*EXP(0.2*$B$5) -> 23390.902 | E26: =_xlfn.NORM.DIST(LN(D26/$B$2), 0, $B$5, FALSE)/D26 -> 0.00040673779
D27: =$D26*EXP(0.2*$B$5) -> 23533.783 | E27: =_xlfn.NORM.DIST(LN(D27/$B$2), 0, $B$5, FALSE)/D27 -> 0.00033767332
D28: =$D27*EXP(0.2*$B$5) -> 23677.536 | E28: =_xlfn.NORM.DIST(LN(D28/$B$2), 0, $B$5, FALSE)/D28 -> 0.00026934392
D29: =$D28*EXP(0.2*$B$5) -> 23822.168 | E29: =_xlfn.NORM.DIST(LN(D29/$B$2), 0, $B$5, FALSE)/D29 -> 0.00020641718
D30: =$D29*EXP(0.2*$B$5) -> 23967.683 | E30: =_xlfn.NORM.DIST(LN(D30/$B$2), 0, $B$5, FALSE)/D30 -> 0.0001519892
D31: =$D30*EXP(0.2*$B$5) -> 24114.088 | E31: =_xlfn.NORM.DIST(LN(D31/$B$2), 0, $B$5, FALSE)/D31 -> 0.0001075246
D32: =$D31*EXP(0.2*$B$5) -> 24261.386 | E32: =_xlfn.NORM.DIST(LN(D32/$B$2), 0, $B$5, FALSE)/D32 -> 7.3085487e-05
... D64: =$D63*EXP(0.2*$B$5) -> 29481.42 | E64: =_xlfn.NORM.DIST(LN(D64/$B$2), 0, $B$5, FALSE)/D64 -> 2.1177662e-19

Sheet Monte Carlo Simulation
A1: Spot Price (S) | B1: 22828
A2: Strike Price (K) | B2: 22900
A3: Risk-Free Rate (r) | B3: 0.07
A4: Volatility (Sigma) | B4: 0.1939
A5: Time to Expiry (T) | B5: 0.02466
A6: No. of Simulations | B6: 5000
A8: CONSTANTS
A9: Drift Component (μ - ½σ²) | B9: =B3 - 0.5*B4^2 -> 0.051201395
A10: Diffusion Component (σ√T) | B10: =B4*SQRT(B5) -> 0.030449092
A11: MONTE CARLO TABLE
A12: Sim # | B12: Random Normal Z | C12: Simulated Price | D12: Payoff (Call) | E12: Potential Loss
A13: 1 | B13: =_xlfn.NORM.S.INV(RAND()) -> 0.82760344 | C13: =B$1*EXP(B$9*B$5 + $B$10*B13) -> 23440.147 | D13: =MAX(C13 - B$2, 0) -> 540.14738 | E13: =$D$5014-D13 -> -281.51326
A14: =A13+1 -> 2 | B14: =_xlfn.NORM.S.INV(RAND()) -> -0.24330682 | C14: =B$1*EXP(B$9*B$5 + $B$10*B14) -> 22688.133 | D14: =MAX(C14 - B$2, 0) -> 0 | E14: =$D$5014-D14 -> 258.63412
A15: =A14+1 -> 3 | B15: =_xlfn.NORM.S.INV(RAND()) -> -1.4514064 | C15: =B$1*EXP(B$9*B$5 + $B$10*B15) -> 21868.702 | D15: =MAX(C15 - B$2, 0) -> 0 | E15: =$D$5014-D15 -> 258.63412
A16: =A15+1 -> 4 | B16: =_xlfn.NORM.S.INV(RAND()) -> 0.31702989 | C16: =B$1*EXP(B$9*B$5 + $B$10*B16) -> 23078.553 | D16: =MAX(C16 - B$2, 0) -> 178.55315 | E16: =$D$5014-D16 -> 80.080969
A17: =A16+1 -> 5 | B17: =_xlfn.NORM.S.INV(RAND()) -> -1.7419604 | C17: =B$1*EXP(B$9*B$5 + $B$10*B17) -> 21676.08 | D17: =MAX(C17 - B$2, 0) -> 0 | E17: =$D$5014-D17 -> 258.63412
A18: =A17+1 -> 6 | B18: =_xlfn.NORM.S.INV(RAND()) -> -0.95760827 | C18: =B$1*EXP(B$9*B$5 + $B$10*B18) -> 22199.998 | D18: =MAX(C18 - B$2, 0) -> 0 | E18: =$D$5014-D18 -> 258.63412
A19: =A18+1 -> 7 | B19: =_xlfn.NORM.S.INV(RAND()) -> -0.77523441 | C19: =B$1*EXP(B$9*B$5 + $B$10*B19) -> 22323.62 | D19: =MAX(C19 - B$2, 0) -> 0 | E19: =$D$5014-D19 -> 258.63412
A20: =A19+1 -> 8 | B20: =_xlfn.NORM.S.INV(RAND()) -> -0.55647012 | C20: =B$1*EXP(B$9*B$5 + $B$10*B20) -> 22472.818 | D20: =MAX(C20 - B$2, 0) -> 0 | E20: =$D$5014-D20 -> 258.63412
A21: =A20+1 -> 9 | B21: =_xlfn.NORM.S.INV(RAND()) -> -0.75141548 | C21: =B$1*EXP(B$9*B$5 + $B$10*B21) -> 22339.816 | D21: =MAX(C21 - B$2, 0) -> 0 | E21: =$D$5014-D21 -> 258.63412
A22: =A21+1 -> 10 | B22: =_xlfn.NORM.S.INV(RAND()) -> 0.9814684 | C22: =B$1*EXP(B$9*B$5 + $B$10*B22) -> 23550.223 | D22: =MAX(C22 - B$2, 0) -> 650.22326 | E22: =$D$5014-D22 -> -391.58913
A23: =A22+1 -> 11 | B23: =_xlfn.NORM.S.INV(RAND()) -> -1.1761373 | C23: =B$1*EXP(B$9*B$5 + $B$10*B23) -> 22052.769 | D23: =MAX(C23 - B$2, 0) -> 0 | E23: =$D$5014-D23 -> 258.63412
A24: =A23+1 -> 12 | B24: =_xlfn.NORM.S.INV(RAND()) -> -0.85280044 | C24: =B$1*EXP(B$9*B$5 + $B$10*B24) -> 22270.958 | D24: =MAX(C24 - B$2, 0) -> 0 | E24: =$D$5014-D24 -> 258.63412
A25: =A24+1 -> 13 | B25: =_xlfn.NORM.S.INV(RAND()) -> 2.9876952 | C25: =B$1*EXP(B$9*B$5 + $B$10*B25) -> 25033.704 | D25: =MAX(C25 - B$2, 0) -> 2133.7042 | E25: =$D$5014-D25 -> -1875.07
... A5012: =A5011+1 -> 5000 | B5012: =_xlfn.NORM.S.INV(RAND()) -> -0.30543323 | C5012: =B$1*EXP(B$9*B$5 + $B$10*B5012) -> 22645.254 | D5012: =MAX(C5012 - B$2, 0) -> 0 | E5012: =$D$5014-D5012 -> 258.63412
C5014: Average Payoff | D5014: =AVERAGE(D13:D5012) -> 258.63412
C5015: Present value of avg payoff (Monte Caro Estimated Option Price) | D5015: =D5014*EXP(-B3*B5) -> 258.18805
A5018: Probability of Expiring ITM | B5018: =COUNTIF(D13:D5012,">0")/5000 -> 0.4566
A5019: Probability of Profit | B5019: =COUNTIF(D13:D5012, ">" & D5014) / 5000 -> 0.3254
A5020: Probability of Loss | B5020: =COUNTIF(D13:D5012, "<" & D5014) / 5000 -> 0.6746
A5021: Probability of Option Expiring Worthless (Payoff = 0) | B5021: =COUNTIF(D13:D5012, "=0") / 5000 -> 0.5434
A5023: RISK EVALUATION
A5024: Std Dev of Payoffs (Risk spread) | B5024: =_xlfn.STDEV.P(D13:D5012) -> 405.73073
A5025: Worst Case Payoff (Minimum) | B5025: =MIN(D13:D5012) -> 0
A5026: Best Case Payoff (Maximum) | B5026: =MAX(D13:D5012) -> 3245.6771
A5027: Value at Risk (VaR @ 5%) | B5027: =_xlfn.PERCENTILE.INC(E13:E5012, 0.05) -> -891.84846

Sheet NIFTY 50_HistoricalData
A1: Date | B1: Close | C1: Open | D1: Daily % Change | E1: Jump > 2%? | F1: Total Days | G1: =COUNTA(D3:D1245) -> 1243
A2: 45764 | B2: 23851.65 | C2: 23401.85 | D2: =(C2-B3)/B3 -> -0.001508286 | F2: Jump Days | G2: =SUM(G6:G7) -> 16
A3: 45763 | B3: 23437.2 | C3: 23344.1 | D3: =(C3-B4)/B4 -> 0.00066656522 | E3: =IF(ABS(D3)>2%,1,0) -> 0 | F3: % Days with change of 2% | G3: =G2/G1 -> 0.012872084
A4: 45762 | B4: 23328.55 | C4: 23368.35 | D4: =(C4-B5)/B5 -> 0.023645829 | E4: =IF(ABS(D4)>2%,1,0) -> 1
A5: 45758 | B5: 22828.55 | C5: 22695.4 | D5: =(C5-B6)/B6 -> 0.013225948 | E5: =IF(ABS(D5)>2%,1,0) -> 0
A6: 45756 | B6: 22399.15 | C6: 22460.3 | D6: =(C6-B7)/B7 -> -0.0033524362 | E6: =IF(ABS(D6)>2%,1,0) -> 0 | F6: No. of days with 2% Jump | G6: =COUNTIF(D:D, ">0.02") -> 6 | H6: % Days with positive 2% jump | I6: =G6/G1 -> 0.0048270314
A7: 45755 | B7: 22535.85 | C7: 22446.75 | D7: =(C7-B8)/B8 -> 0.012866851 | E7: =IF(ABS(D7)>2%,1,0) -> 0 | F7: No. of days with 2% Fall | G7: =COUNTIF(D:D, "<-0.02") -> 10 | H7: % Days with negative 2% jump | I7: =G7/G1 -> 0.0080450523
A8: 45754 | B8: 22161.6 | C8: 21758.4 | D8: =(C8-B9)/B9 -> -0.050036128 | E8: =IF(ABS(D8)>2%,1,0) -> 1 | F8: Normal Days (Less than 2% Movement) | G8: =G1-G2 -> 1227 | H8: % of Normal Days | I8: =G8/G1 -> 0.98712792
A9: 45751 | B9: 22904.45 | C9: 23190.4 | D9: =(C9-B10)/B10 -> -0.0025677309 | E9: =IF(ABS(D9)>2%,1,0) -> 0
A10: 45750 | B10: 23250.1 | C10: 23150.3 | D10: =(C10-B11)/B11 -> -0.0078024717 | E10: =IF(ABS(D10)>2%,1,0) -> 0
A11: 45749 | B11: 23332.35 | C11: 23192.6 | D11: =(C11-B12)/B12 -> 0.0011611995 | E11: =IF(ABS(D11)>2%,1,0) -> 0
A12: 45748 | B12: 23165.7 | C12: 23341.1 | D12: =(C12-B13)/B13 -> -0.0075788659 | E12: =IF(ABS(D12)>2%,1,0) -> 0
A13: 45744 | B13: 23519.35 | C13: 23600.4 | D13: =(C13-B14)/B14 -> 0.00035817302 | E13: =IF(ABS(D13)>2%,1,0) -> 0
A14: 45743 | B14: 23591.95 | C14: 23433.95 | D14: =(C14-B15)/B15 -> -0.0022523242 | E14: =IF(ABS(D14)>2%,1,0) -> 0
A15: 45742 | B15: 23486.85 | C15: 23700.95 | D15: =(C15-B16)/B16 -> 0.0013646744 | E15: =IF(ABS(D15)>2%,1,0) -> 0
A16: 45741 | B16: 23668.65 | C16: 23751.5 | D16: =(C16-B17)/B17 -> 0.0039372991 | E16: =IF(ABS(D16)>2%,1,0) -> 0
A17: 45740 | B17: 23658.35 | C17: 23515.4 | D17: =(C17-B18)/B18 -> 0.0070662601 | E17: =IF(ABS(D17)>2%,1,0) -> 0
A18: 45737 | B18: 23350.4 | C18: 23168.25 | D18: =(C18-B19)/B19 -> -0.00096590652 | E18: =IF(ABS(D18)>2%,1,0) -> 0
A19: 45736 | B19: 23190.65 | C19: 23036.6 | D19: =(C19-B20)/B20 -> 0.0056313189 | E19: =IF(ABS(D19)>2%,1,0) -> 0
A20: 45735 | B20: 22907.6 | C20: 22874.95 | D20: =(C20-B21)/B21 -> 0.0017802166 | E20: =IF(ABS(D20)>2%,1,0) -> 0
... A1245: 43938 | B1245: 9266.75 | C1245: 9323.45 | D1245: =(C1245-B1246)/B1246 -> #DIV/0! | E1245: =IF(ABS(D1245)>2%,1,0) -> #DIV/0!

Sheet News
A1: Date | B1: Close | C1: Open | D1: Daily % Change | E1: News
A2: 45762 | B2: 23328.55 | C2: 23368.35 | D2: 0.023645829 | E2: Trump Tariff exemptions
A3: 45446 | B3: 23263.9 | C3: 23337.9 | D3: 0.035826672 | E3: Exit Polls
A4: 44630 | B4: 16594.9 | C4: 16757.1 | D4: 0.025190651 | E4: Assembly Election results
A5: 43998 | B5: 9914 | C5: 10014.8 | D5: 0.020491762 | E5: India China tensions in Ladakh
A6: 43964 | B6: 9383.55 | C6: 9584.2 | D6: 0.042151676 | E6: Modi Stimulus boost
A7: 43951 | B7: 9859.9 | C7: 9753.5 | D7: 0.020950766 | E7: Encouraging COVID 19 treatment trial

Sheet NIFTY movement on Thursdays 
A1: Date | B1: Open | C1: High | D1: Low | E1: Close | F1: Weekday | G1: Market move on Thursday | H1: Intraday range on Thursday | I1: How Thursday opened compared to Wednesday's close | J1: Thursday Direction | K1: High Movement | L1: News
A2: 45764 | B2: 23401.85 | C2: 23872.35 | D2: 23298.55 | E2: 23851.65 | F2: =TEXT(A2, "dddd") -> Thursday | G2: =(E2 - B2)/B2 -> 0.019220703 | H2: =(C2 - D2)/B2 -> 0.024519429 | I2: =(B2-E3)/E3 -> -0.001508286 | J2: =IF(F2="Thursday", IF(G2>0,"Positive","Negative"), "") -> Positive | K2: =IF(F2="Thursday", IF(ABS(G2)>1%, "High Move", ""), "") -> High Move | L2: FII Inflows, Strengthening Rupee against USD
A3: 45763 | B3: 23344.1 | C3: 23452.2 | D3: 23273.05 | E3: 23437.2 | F3: =TEXT(A3, "dddd") -> Wednesday | G3: =(E3 - B3)/B3 -> 0.0039881597 | H3: =(C3 - D3)/B3 -> 0.007674316 | I3: =(B3-E4)/E4 -> 0.00066656522 | J3: =IF(F3="Thursday", IF(G3>0,"Positive","Negative"), "") | K3: =IF(F3="Thursday", IF(ABS(G3)>1%, "High Move", ""), "")
A4: 45762 | B4: 23368.35 | C4: 23368.35 | D4: 23207 | E4: 23328.55 | F4: =TEXT(A4, "dddd") -> Tuesday | G4: =(E4 - B4)/B4 -> -0.0017031583 | H4: =(C4 - D4)/B4 -> 0.0069046381 | I4: =(B4-E5)/E5 -> 0.023645829 | J4: =IF(F4="Thursday", IF(G4>0,"Positive","Negative"), "") | K4: =IF(F4="Thursday", IF(ABS(G4)>1%, "High Move", ""), "")
A5: 45758 | B5: 22695.4 | C5: 22923.9 | D5: 22695.4 | E5: 22828.55 | F5: =TEXT(A5, "dddd") -> Friday | G5: =(E5 - B5)/B5 -> 0.0058668276 | H5: =(C5 - D5)/B5 -> 0.01006812 | I5: =(B5-E6)/E6 -> 0.013225948 | J5: =IF(F5="Thursday", IF(G5>0,"Positive","Negative"), "") | K5: =IF(F5="Thursday", IF(ABS(G5)>1%, "High Move", ""), "")
A6: 45756 | B6: 22460.3 | C6: 22468.7 | D6: 22353.25 | E6: 22399.15 | F6: =TEXT(A6, "dddd") -> Wednesday | G6: =(E6 - B6)/B6 -> -0.0027225816 | H6: =(C6 - D6)/B6 -> 0.0051401807 | I6: =(B6-E7)/E7 -> -0.0033524362 | J6: =IF(F6="Thursday", IF(G6>0,"Positive","Negative"), "") | K6: =IF(F6="Thursday", IF(ABS(G6)>1%, "High Move", ""), "")
A7: 45755 | B7: 22446.75 | C7: 22697.2 | D7: 22270.85 | E7: 22535.85 | F7: =TEXT(A7, "dddd") -> Tuesday | G7: =(E7 - B7)/B7 -> 0.0039693942 | H7: =(C7 - D7)/B7 -> 0.018993841 | I7: =(B7-E8)/E8 -> 0.012866851 | J7: =IF(F7="Thursday", IF(G7>0,"Positive","Negative"), "") | K7: =IF(F7="Thursday", IF(ABS(G7)>1%, "High Move", ""), "")
A8: 45754 | B8: 21758.4 | C8: 22254 | D8: 21743.65 | E8: 22161.6 | F8: =TEXT(A8, "dddd") -> Monday | G8: =(E8 - B8)/B8 -> 0.018530774 | H8: =(C8 - D8)/B8 -> 0.023455309 | I8: =(B8-E9)/E9 -> -0.050036128 | J8: =IF(F8="Thursday", IF(G8>0,"Positive","Negative"), "") | K8: =IF(F8="Thursday", IF(ABS(G8)>1%, "High Move", ""), "")
A9: 45751 | B9: 23190.4 | C9: 23214.7 | D9: 22857.45 | E9: 22904.45 | F9: =TEXT(A9, "dddd") -> Friday | G9: =(E9 - B9)/B9 -> -0.012330533 | H9: =(C9 - D9)/B9 -> 0.015405081 | I9: =(B9-E10)/E10 -> -0.0025677309 | J9: =IF(F9="Thursday", IF(G9>0,"Positive","Negative"), "") | K9: =IF(F9="Thursday", IF(ABS(G9)>1%, "High Move", ""), "")
A10: 45750 | B10: 23150.3 | C10: 23306.5 | D10: 23145.8 | E10: 23250.1 | F10: =TEXT(A10, "dddd") -> Thursday | G10: =(E10 - B10)/B10 -> 0.0043109593 | H10: =(C10 - D10)/B10 -> 0.0069415947 | I10: =(B10-E11)/E11 -> -0.0078024717 | J10: =IF(F10="Thursday", IF(G10>0,"Positive","Negative"), "") -> Positive | K10: =IF(F10="Thursday", IF(ABS(G10)>1%, "High Move", ""), "")
A11: 45749 | B11: 23192.6 | C11: 23350 | D11: 23158.45 | E11: 23332.35 | F11: =TEXT(A11, "dddd") -> Wednesday | G11: =(E11 - B11)/B11 -> 0.0060256289 | H11: =(C11 - D11)/B11 -> 0.0082590999 | I11: =(B11-E12)/E12 -> 0.0011611995 | J11: =IF(F11="Thursday", IF(G11>0,"Positive","Negative"), "") | K11: =IF(F11="Thursday", IF(ABS(G11)>1%, "High Move", ""), "")
A12: 45748 | B12: 23341.1 | C12: 23565.15 | D12: 23136.4 | E12: 23165.7 | F12: =TEXT(A12, "dddd") -> Tuesday | G12: =(E12 - B12)/B12 -> -0.0075146416 | H12: =(C12 - D12)/B12 -> 0.018368886 | I12: =(B12-E13)/E13 -> -0.0075788659 | J12: =IF(F12="Thursday", IF(G12>0,"Positive","Negative"), "") | K12: =IF(F12="Thursday", IF(ABS(G12)>1%, "High Move", ""), "")
A13: 45744 | B13: 23600.4 | C13: 23649.2 | D13: 23450.2 | E13: 23519.35 | F13: =TEXT(A13, "dddd") -> Friday | G13: =(E13 - B13)/B13 -> -0.0034342638 | H13: =(C13 - D13)/B13 -> 0.0084320605 | I13: =(B13-E14)/E14 -> 0.00035817302 | J13: =IF(F13="Thursday", IF(G13>0,"Positive","Negative"), "") | K13: =IF(F13="Thursday", IF(ABS(G13)>1%, "High Move", ""), "")
A14: 45743 | B14: 23433.95 | C14: 23646.45 | D14: 23412.2 | E14: 23591.95 | F14: =TEXT(A14, "dddd") -> Thursday | G14: =(E14 - B14)/B14 -> 0.0067423546 | H14: =(C14 - D14)/B14 -> 0.0099961808 | I14: =(B14-E15)/E15 -> -0.0022523242 | J14: =IF(F14="Thursday", IF(G14>0,"Positive","Negative"), "") -> Positive | K14: =IF(F14="Thursday", IF(ABS(G14)>1%, "High Move", ""), "")
... A1245: 43938 | B1245: 9323.45 | C1245: 9324 | D1245: 9091.35 | E1245: 9266.75 | F1245: =TEXT(A1245, "dddd") -> Friday | G1245: =(E1245 - B1245)/B1245 -> -0.0060814398 | H1245: =(C1245 - D1245)/B1245 -> 0.024953209 | I1245: =(B1245-E1246)/E1246 -> #DIV/0! | J1245: =IF(F1245="Thursday", IF(G1245>0,"Positive","Negative"), "") | K1245: =IF(F1245="Thursday", IF(ABS(G1245)>1%, "High Move", ""), "")

Sheet Data Metrics
A2: Avg Return on Thursdays | B2: =AVERAGE('NIFTY movement on Thursdays '!G2:G1245) -> -0.0005136049
A3: Std Dev of Returns | B3: =_xlfn.STDEV.P('NIFTY movement on Thursdays '!G2:G1245) -> 0.0078702762
A4: Positive Thursdays Count | B4: =COUNTIF('NIFTY movement on Thursdays '!G2:G1245, ">0") -> 611
A5: Negative Thursdays Count | B5: =COUNTIF('NIFTY movement on Thursdays '!G2:G1245, "<0") -> 633
A6: Max Thursdays Return | B6: =MAX('NIFTY movement on Thursdays '!G2:G1245) -> 0.044835227
A7: Min Thursdays Return | B7: =MIN('NIFTY movement on Thursdays '!G2:G1245) -> -0.055868332

Sheet 3rd Day Trading Pattern
A1: Date | B1: Close | C1: Daily Returns | D1: Up/Down | E1: 2-Day Down Streak | F1: 3rd Day Return | G1: Was 3rd Day Up?
A2: 43938 | B2: 9266.75 | F2: =IF(E1="Yes", C1, "") | G2: =IF(E2="Yes", IF(F2>0, "Yes", "No"), "")
A3: 43941 | B3: 9261.85 | C3: =(B3-B2)/B2 -> -0.00052877222 | D3: =IF(C3>0, "Up", IF(C3<0, "Down", "Flat")) -> Down | F3: =IF(E2="Yes", C2, "") | G3: =IF(E3="Yes", IF(F3>0, "Yes", "No"), "")
A4: 43942 | B4: 8981.45 | C4: =(B4-B3)/B3 -> -0.030274729 | D4: =IF(C4>0, "Up", IF(C4<0, "Down", "Flat")) -> Down | E4: =IF(AND(D2="Down", D3="Down"), "Yes", "No") -> No | F4: =IF(E3="Yes", C3, "") | G4: =IF(E4="Yes", IF(F4>0, "Yes", "No"), "")
A5: 43943 | B5: 9187.3 | C5: =(B5-B4)/B4 -> 0.022919462 | D5: =IF(C5>0, "Up", IF(C5<0, "Down", "Flat")) -> Up | E5: =IF(AND(D3="Down", D4="Down"), "Yes", "No") -> Yes | F5: =IF(E5="Yes", C5, "") -> 0.022919462 | G5: =IF(E5="Yes", IF(F5>0, "Yes", "No"), "") -> Yes
A6: 43944 | B6: 9313.9 | C6: =(B6-B5)/B5 -> 0.013779892 | D6: =IF(C6>0, "Up", IF(C6<0, "Down", "Flat")) -> Up | E6: =IF(AND(D4="Down", D5="Down"), "Yes", "No") -> No | F6: =IF(E6="Yes", C6, "") | G6: =IF(E6="Yes", IF(F6>0, "Yes", "No"), "")
A7: 43945 | B7: 9154.4 | C7: =(B7-B6)/B6 -> -0.017124942 | D7: =IF(C7>0, "Up", IF(C7<0, "Down", "Flat")) -> Down | E7: =IF(AND(D5="Down", D6="Down"), "Yes", "No") -> No | F7: =IF(E7="Yes", C7, "") | G7: =IF(E7="Yes", IF(F7>0, "Yes", "No"), "") | M7: Count of 2-Day Down | N7: =COUNTIF(E:E, "Yes") -> 279
A8: 43948 | B8: 9282.3 | C8: =(B8-B7)/B7 -> 0.013971424 | D8: =IF(C8>0, "Up", IF(C8<0, "Down", "Flat")) -> Up | E8: =IF(AND(D6="Down", D7="Down"), "Yes", "No") -> No | F8: =IF(E8="Yes", C8, "") | G8: =IF(E8="Yes", IF(F8>0, "Yes", "No"), "") | M8: Count of 3rd Day up | N8: =COUNTIF(G:G, "Yes") -> 134
A9: 43949 | B9: 9380.9 | C9: =(B9-B8)/B8 -> 0.010622367 | D9: =IF(C9>0, "Up", IF(C9<0, "Down", "Flat")) -> Up | E9: =IF(AND(D7="Down", D8="Down"), "Yes", "No") -> No | F9: =IF(E9="Yes", C9, "") | G9: =IF(E9="Yes", IF(F9>0, "Yes", "No"), "") | M9: % of times | N9: =N8/N7 -> 0.48028674
A10: 43950 | B10: 9553.35 | C10: =(B10-B9)/B9 -> 0.018383098 | D10: =IF(C10>0, "Up", IF(C10<0, "Down", "Flat")) -> Up | E10: =IF(AND(D8="Down", D9="Down"), "Yes", "No") -> No | F10: =IF(E10="Yes", C10, "") | G10: =IF(E10="Yes", IF(F10>0, "Yes", "No"), "") | M10: Average Return on 3rd Day (When Up) | N10: =AVERAGEIFS(F:F, G:G, "Yes") -> 0.0083781095
A11: 43951 | B11: 9859.9 | C11: =(B11-B10)/B10 -> 0.03208822 | D11: =IF(C11>0, "Up", IF(C11<0, "Down", "Flat")) -> Up | E11: =IF(AND(D9="Down", D10="Down"), "Yes", "No") -> No | F11: =IF(E11="Yes", C11, "") | G11: =IF(E11="Yes", IF(F11>0, "Yes", "No"), "") | M11: Average Return on All 3rd Days (Even if Down) | N11: =AVERAGEIF(E:E, "Yes", F:F) -> -0.00031428461
A12: 43955 | B12: 9293.5 | C12: =(B12-B11)/B11 -> -0.057444802 | D12: =IF(C12>0, "Up", IF(C12<0, "Down", "Flat")) -> Down | E12: =IF(AND(D10="Down", D11="Down"), "Yes", "No") -> No | F12: =IF(E12="Yes", C12, "") | G12: =IF(E12="Yes", IF(F12>0, "Yes", "No"), "")
A13: 43956 | B13: 9205.6 | C13: =(B13-B12)/B12 -> -0.0094582235 | D13: =IF(C13>0, "Up", IF(C13<0, "Down", "Flat")) -> Down | E13: =IF(AND(D11="Down", D12="Down"), "Yes", "No") -> No | F13: =IF(E13="Yes", C13, "") | G13: =IF(E13="Yes", IF(F13>0, "Yes", "No"), "") | M13: Up | N13: =COUNTIF(G:G, "Yes") -> 134
A14: 43957 | B14: 9270.9 | C14: =(B14-B13)/B13 -> 0.0070935083 | D14: =IF(C14>0, "Up", IF(C14<0, "Down", "Flat")) -> Up | E14: =IF(AND(D12="Down", D13="Down"), "Yes", "No") -> Yes | F14: =IF(E14="Yes", C14, "") -> 0.0070935083 | G14: =IF(E14="Yes", IF(F14>0, "Yes", "No"), "") -> Yes | M14: Down | N14: =COUNTIF(G:G, "No") -> 145
A15: 43958 | B15: 9199.05 | C15: =(B15-B14)/B14 -> -0.0077500566 | D15: =IF(C15>0, "Up", IF(C15<0, "Down", "Flat")) -> Down | E15: =IF(AND(D13="Down", D14="Down"), "Yes", "No") -> No | F15: =IF(E15="Yes", C15, "") | G15: =IF(E15="Yes", IF(F15>0, "Yes", "No"), "")
A16: 43959 | B16: 9251.5 | C16: =(B16-B15)/B15 -> 0.0057016757 | D16: =IF(C16>0, "Up", IF(C16<0, "Down", "Flat")) -> Up | E16: =IF(AND(D14="Down", D15="Down"), "Yes", "No") -> No | F16: =IF(E16="Yes", C16, "") | G16: =IF(E16="Yes", IF(F16>0, "Yes", "No"), "")
A17: 43962 | B17: 9239.2 | C17: =(B17-B16)/B16 -> -0.0013295141 | D17: =IF(C17>0, "Up", IF(C17<0, "Down", "Flat")) -> Down | E17: =IF(AND(D15="Down", D16="Down"), "Yes", "No") -> No | F17: =IF(E17="Yes", C17, "") | G17: =IF(E17="Yes", IF(F17>0, "Yes", "No"), "")
A18: 43963 | B18: 9196.55 | C18: =(B18-B17)/B17 -> -0.0046162005 | D18: =IF(C18>0, "Up", IF(C18<0, "Down", "Flat")) -> Down | E18: =IF(AND(D16="Down", D17="Down"), "Yes", "No") -> No | F18: =IF(E18="Yes", C18, "") | G18: =IF(E18="Yes", IF(F18>0, "Yes", "No"), "")
A19: 43964 | B19: 9383.55 | C19: =(B19-B18)/B18 -> 0.020333712 | D19: =IF(C19>0, "Up", IF(C19<0, "Down", "Flat")) -> Up | E19: =IF(AND(D17="Down", D18="Down"), "Yes", "No") -> Yes | F19: =IF(E19="Yes", C19, "") -> 0.020333712 | G19: =IF(E19="Yes", IF(F19>0, "Yes", "No"), "") -> Yes
A20: 43965 | B20: 9142.75 | C20: =(B20-B19)/B19 -> -0.02566193 | D20: =IF(C20>0, "Up", IF(C20<0, "Down", "Flat")) -> Down | E20: =IF(AND(D18="Down", D19="Down"), "Yes", "No") -> No | F20: =IF(E20="Yes", C20, "") | G20: =IF(E20="Yes", IF(F20>0, "Yes", "No"), "")
A21: 43966 | B21: 9136.85 | C21: =(B21-B20)/B20 -> -0.00064532006 | D21: =IF(C21>0, "Up", IF(C21<0, "Down", "Flat")) -> Down | E21: =IF(AND(D19="Down", D20="Down"), "Yes", "No") -> No | F21: =IF(E21="Yes", C21, "") | G21: =IF(E21="Yes", IF(F21>0, "Yes", "No"), "")
A22: 43969 | B22: 8823.25 | C22: =(B22-B21)/B21 -> -0.034322551 | D22: =IF(C22>0, "Up", IF(C22<0, "Down", "Flat")) -> Down | E22: =IF(AND(D20="Down", D21="Down"), "Yes", "No") -> Yes | F22: =IF(E22="Yes", C22, "") -> -0.034322551 | G22: =IF(E22="Yes", IF(F22>0, "Yes", "No"), "") -> No
A23: 43970 | B23: 8879.1 | C23: =(B23-B22)/B22 -> 0.0063298671 | D23: =IF(C23>0, "Up", IF(C23<0, "Down", "Flat")) -> Up | E23: =IF(AND(D21="Down", D22="Down"), "Yes", "No") -> Yes | F23: =IF(E23="Yes", C23, "") -> 0.0063298671 | G23: =IF(E23="Yes", IF(F23>0, "Yes", "No"), "") -> Yes
A24: 43971 | B24: 9066.55 | C24: =(B24-B23)/B23 -> 0.021111374 | D24: =IF(C24>0, "Up", IF(C24<0, "Down", "Flat")) -> Up | E24: =IF(AND(D22="Down", D23="Down"), "Yes", "No") -> No | F24: =IF(E24="Yes", C24, "") | G24: =IF(E24="Yes", IF(F24>0, "Yes", "No"), "")
A25: 43972 | B25: 9106.25 | C25: =(B25-B24)/B24 -> 0.0043787328 | D25: =IF(C25>0, "Up", IF(C25<0, "Down", "Flat")) -> Up | E25: =IF(AND(D23="Down", D24="Down"), "Yes", "No") -> No | F25: =IF(E25="Yes", C25, "") | G25: =IF(E25="Yes", IF(F25>0, "Yes", "No"), "")
A26: 43973 | B26: 9039.25 | C26: =(B26-B25)/B25 -> -0.0073575841 | D26: =IF(C26>0, "Up", IF(C26<0, "Down", "Flat")) -> Down | E26: =IF(AND(D24="Down", D25="Down"), "Yes", "No") -> No | F26: =IF(E26="Yes", C26, "") | G26: =IF(E26="Yes", IF(F26>0, "Yes", "No"), "")
... A1245: 45764 | B1245: 23851.65 | C1245: =(B1245-B1244)/B1244 -> 0.017683426 | D1245: =IF(C1245>0, "Up", IF(C1245<0, "Down", "Flat")) -> Up | E1245: =IF(AND(D1243="Down", D1244="Down"), "Yes", "No") -> No | F1245: =IF(E1245="Yes", C1245, "") | G1245: =IF(E1245="Yes", IF(F1245>0, "Yes", "No"), "")

Sheet 4th day Trading Pattern
A1: Date | B1: Close | C1: Daily Returns | D1: Up/Down | E1: 3-Day Down Streak | F1: 4th Day Return | G1: Was 4th Day Up?
A2: 43938 | B2: 9266.75 | G2: =IF(E2="Yes", IF(F2>0, "Yes", "No"), "")
A3: 43941 | B3: 9261.85 | C3: =(B3-B2)/B2 -> -0.00052877222 | D3: =IF(C3>0, "Up", IF(C3<0, "Down", "Flat")) -> Down | G3: =IF(E3="Yes", IF(F3>0, "Yes", "No"), "")
A4: 43942 | B4: 8981.45 | C4: =(B4-B3)/B3 -> -0.030274729 | D4: =IF(C4>0, "Up", IF(C4<0, "Down", "Flat")) -> Down | G4: =IF(E4="Yes", IF(F4>0, "Yes", "No"), "")
A5: 43943 | B5: 9187.3 | C5: =(B5-B4)/B4 -> 0.022919462 | D5: =IF(C5>0, "Up", IF(C5<0, "Down", "Flat")) -> Up | E5: =IF(AND(D2="Down", D3="Down", D4="Down"), "Yes", "No") -> No | F5: =IF(E5="Yes", C5, "") | G5: =IF(E5="Yes", IF(F5>0, "Yes", "No"), "")
A6: 43944 | B6: 9313.9 | C6: =(B6-B5)/B5 -> 0.013779892 | D6: =IF(C6>0, "Up", IF(C6<0, "Down", "Flat")) -> Up | E6: =IF(AND(D3="Down", D4="Down", D5="Down"), "Yes", "No") -> No | F6: =IF(E6="Yes", C6, "") | G6: =IF(E6="Yes", IF(F6>0, "Yes", "No"), "") | M6: Count of 3-Day Down | N6: =COUNTIF(E:E, "Yes") -> 144
A7: 43945 | B7: 9154.4 | C7: =(B7-B6)/B6 -> -0.017124942 | D7: =IF(C7>0, "Up", IF(C7<0, "Down", "Flat")) -> Down | E7: =IF(AND(D4="Down", D5="Down", D6="Down"), "Yes", "No") -> No | F7: =IF(E7="Yes", C7, "") | G7: =IF(E7="Yes", IF(F7>0, "Yes", "No"), "") | M7: Count of 4th Day up | N7: =COUNTIF(G:G, "Yes") -> 65
A8: 43948 | B8: 9282.3 | C8: =(B8-B7)/B7 -> 0.013971424 | D8: =IF(C8>0, "Up", IF(C8<0, "Down", "Flat")) -> Up | E8: =IF(AND(D5="Down", D6="Down", D7="Down"), "Yes", "No") -> No | F8: =IF(E8="Yes", C8, "") | G8: =IF(E8="Yes", IF(F8>0, "Yes", "No"), "") | M8: % of times | N8: =N7/N6 -> 0.45138889
A9: 43949 | B9: 9380.9 | C9: =(B9-B8)/B8 -> 0.010622367 | D9: =IF(C9>0, "Up", IF(C9<0, "Down", "Flat")) -> Up | E9: =IF(AND(D6="Down", D7="Down", D8="Down"), "Yes", "No") -> No | F9: =IF(E9="Yes", C9, "") | G9: =IF(E9="Yes", IF(F9>0, "Yes", "No"), "") | M9: Average Return on 4th Day (When Up) | N9: =AVERAGEIFS(F:F, G:G, "Yes") -> 0.0080536395
A10: 43950 | B10: 9553.35 | C10: =(B10-B9)/B9 -> 0.018383098 | D10: =IF(C10>0, "Up", IF(C10<0, "Down", "Flat")) -> Up | E10: =IF(AND(D7="Down", D8="Down", D9="Down"), "Yes", "No") -> No | F10: =IF(E10="Yes", C10, "") | G10: =IF(E10="Yes", IF(F10>0, "Yes", "No"), "") | M10: Average Return on All 4th Days (Even if Down) | N10: =AVERAGEIF(E:E, "Yes", F:F) -> -0.0014694971
A11: 43951 | B11: 9859.9 | C11: =(B11-B10)/B10 -> 0.03208822 | D11: =IF(C11>0, "Up", IF(C11<0, "Down", "Flat")) -> Up | E11: =IF(AND(D8="Down", D9="Down", D10="Down"), "Yes", "No") -> No | F11: =IF(E11="Yes", C11, "") | G11: =IF(E11="Yes", IF(F11>0, "Yes", "No"), "")
A12: 43955 | B12: 9293.5 | C12: =(B12-B11)/B11 -> -0.057444802 | D12: =IF(C12>0, "Up", IF(C12<0, "Down", "Flat")) -> Down | E12: =IF(AND(D9="Down", D10="Down", D11="Down"), "Yes", "No") -> No | F12: =IF(E12="Yes", C12, "") | G12: =IF(E12="Yes", IF(F12>0, "Yes", "No"), "") | M12: Up | N12: =COUNTIF(G:G, "Yes") -> 65
A13: 43956 | B13: 9205.6 | C13: =(B13-B12)/B12 -> -0.0094582235 | D13: =IF(C13>0, "Up", IF(C13<0, "Down", "Flat")) -> Down | E13: =IF(AND(D10="Down", D11="Down", D12="Down"), "Yes", "No") -> No | F13: =IF(E13="Yes", C13, "") | G13: =IF(E13="Yes", IF(F13>0, "Yes", "No"), "") | M13: Down | N13: =COUNTIF(G:G, "No") -> 79
A14: 43957 | B14: 9270.9 | C14: =(B14-B13)/B13 -> 0.0070935083 | D14: =IF(C14>0, "Up", IF(C14<0, "Down", "Flat")) -> Up | E14: =IF(AND(D11="Down", D12="Down", D13="Down"), "Yes", "No") -> No | F14: =IF(E14="Yes", C14, "") | G14: =IF(E14="Yes", IF(F14>0, "Yes", "No"), "")
A15: 43958 | B15: 9199.05 | C15: =(B15-B14)/B14 -> -0.0077500566 | D15: =IF(C15>0, "Up", IF(C15<0, "Down", "Flat")) -> Down | E15: =IF(AND(D12="Down", D13="Down", D14="Down"), "Yes", "No") -> No | F15: =IF(E15="Yes", C15, "") | G15: =IF(E15="Yes", IF(F15>0, "Yes", "No"), "")
A16: 43959 | B16: 9251.5 | C16: =(B16-B15)/B15 -> 0.0057016757 | D16: =IF(C16>0, "Up", IF(C16<0, "Down", "Flat")) -> Up | E16: =IF(AND(D13="Down", D14="Down", D15="Down"), "Yes", "No") -> No | F16: =IF(E16="Yes", C16, "") | G16: =IF(E16="Yes", IF(F16>0, "Yes", "No"), "")
A17: 43962 | B17: 9239.2 | C17: =(B17-B16)/B16 -> -0.0013295141 | D17: =IF(C17>0, "Up", IF(C17<0, "Down", "Flat")) -> Down | E17: =IF(AND(D14="Down", D15="Down", D16="Down"), "Yes", "No") -> No | F17: =IF(E17="Yes", C17, "") | G17: =IF(E17="Yes", IF(F17>0, "Yes", "No"), "")
A18: 43963 | B18: 9196.55 | C18: =(B18-B17)/B17 -> -0.0046162005 | D18: =IF(C18>0, "Up", IF(C18<0, "Down", "Flat")) -> Down | E18: =IF(AND(D15="Down", D16="Down", D17="Down"), "Yes", "No") -> No | F18: =IF(E18="Yes", C18, "") | G18: =IF(E18="Yes", IF(F18>0, "Yes", "No"), "")
A19: 43964 | B19: 9383.55 | C19: =(B19-B18)/B18 -> 0.020333712 | D19: =IF(C19>0, "Up", IF(C19<0, "Down", "Flat")) -> Up | E19: =IF(AND(D16="Down", D17="Down", D18="Down"), "Yes", "No") -> No | F19: =IF(E19="Yes", C19, "") | G19: =IF(E19="Yes", IF(F19>0, "Yes", "No"), "")
A20: 43965 | B20: 9142.75 | C20: =(B20-B19)/B19 -> -0.02566193 | D20: =IF(C20>0, "Up", IF(C20<0, "Down", "Flat")) -> Down | E20: =IF(AND(D17="Down", D18="Down", D19="Down"), "Yes", "No") -> No | F20: =IF(E20="Yes", C20, "") | G20: =IF(E20="Yes", IF(F20>0, "Yes", "No"), "")
A21: 43966 | B21: 9136.85 | C21: =(B21-B20)/B20 -> -0.00064532006 | D21: =IF(C21>0, "Up", IF(C21<0, "Down", "Flat")) -> Down | E21: =IF(AND(D18="Down", D19="Down", D20="Down"), "Yes", "No") -> No | F21: =IF(E21="Yes", C21, "") | G21: =IF(E21="Yes", IF(F21>0, "Yes", "No"), "")
A22: 43969 | B22: 8823.25 | C22: =(B22-B21)/B21 -> -0.034322551 | D22: =IF(C22>0, "Up", IF(C22<0, "Down", "Flat")) -> Down | E22: =IF(AND(D19="Down", D20="Down", D21="Down"), "Yes", "No") -> No | F22: =IF(E22="Yes", C22, "") | G22: =IF(E22="Yes", IF(F22>0, "Yes", "No"), "")
A23: 43970 | B23: 8879.1 | C23: =(B23-B22)/B22 -> 0.0063298671 | D23: =IF(C23>0, "Up", IF(C23<0, "Down", "Flat")) -> Up | E23: =IF(AND(D20="Down", D21="Down", D22="Down"), "Yes", "No") -> Yes | F23: =IF(E23="Yes", C23, "") -> 0.0063298671 | G23: =IF(E23="Yes", IF(F23>0, "Yes", "No"), "") -> Yes
A24: 43971 | B24: 9066.55 | C24: =(B24-B23)/B23 -> 0.021111374 | D24: =IF(C24>0, "Up", IF(C24<0, "Down", "Flat")) -> Up | E24: =IF(AND(D21="Down", D22="Down", D23="Down"), "Yes", "No") -> No | F24: =IF(E24="Yes", C24, "") | G24: =IF(E24="Yes", IF(F24>0, "Yes", "No"), "")
A25: 43972 | B25: 9106.25 | C25: =(B25-B24)/B24 -> 0.0043787328 | D25: =IF(C25>0, "Up", IF(C25<0, "Down", "Flat")) -> Up | E25: =IF(AND(D22="Down", D23="Down", D24="Down"), "Yes", "No") -> No | F25: =IF(E25="Yes", C25, "") | G25: =IF(E25="Yes", IF(F25>0, "Yes", "No"), "")
... A1245: 45764 | B1245: 23851.65 | C1245: =(B1245-B1244)/B1244 -> 0.017683426 | D1245: =IF(C1245>0, "Up", IF(C1245<0, "Down", "Flat")) -> Up | E1245: =IF(AND(D1242="Down", D1243="Down", D1244="Down"), "Yes", "No") -> No | F1245: =IF(E1245="Yes", C1245, "") | G1245: =IF(E1245="Yes", IF(F1245>0, "Yes", "No"), "")

Sheet 5th Day Trading Pattern
A1: Date | B1: Close | C1: Daily Returns | D1: Up/Down | E1: 4-Day Down Streak | F1: 5th Day Return | G1: Was 5th Day Up?
A2: 43938 | B2: 9266.75 | G2: =IF(E2="4-Day Down Streak", IF(F2>0, "Yes", "No"), "")
A3: 43941 | B3: 9261.85 | C3: =(B3-B2)/B2 -> -0.00052877222 | D3: =IF(C3>0, "Up", IF(C3<0, "Down", "Flat")) -> Down | G3: =IF(E3="4-Day Down Streak", IF(F3>0, "Yes", "No"), "")
A4: 43942 | B4: 8981.45 | C4: =(B4-B3)/B3 -> -0.030274729 | D4: =IF(C4>0, "Up", IF(C4<0, "Down", "Flat")) -> Down | G4: =IF(E4="4-Day Down Streak", IF(F4>0, "Yes", "No"), "")
A5: 43943 | B5: 9187.3 | C5: =(B5-B4)/B4 -> 0.022919462 | D5: =IF(C5>0, "Up", IF(C5<0, "Down", "Flat")) -> Up | E5: =IF(AND(D2="Down", D3="Down", D4="Down", D5="Down"), "4-Day Down Streak", "") | F5: =IF(E5="4-Day Down Streak", C5, "") | G5: =IF(E5="4-Day Down Streak", IF(F5>0, "Yes", "No"), "")
A6: 43944 | B6: 9313.9 | C6: =(B6-B5)/B5 -> 0.013779892 | D6: =IF(C6>0, "Up", IF(C6<0, "Down", "Flat")) -> Up | E6: =IF(AND(D3="Down", D4="Down", D5="Down", D6="Down"), "4-Day Down Streak", "") | F6: =IF(E6="4-Day Down Streak", C6, "") | G6: =IF(E6="4-Day Down Streak", IF(F6>0, "Yes", "No"), "")
A7: 43945 | B7: 9154.4 | C7: =(B7-B6)/B6 -> -0.017124942 | D7: =IF(C7>0, "Up", IF(C7<0, "Down", "Flat")) -> Down | E7: =IF(AND(D3="Down", D4="Down", D5="Down", D6="Down"), "4-Day Down Streak", "") | F7: =IF(E7="4-Day Down Streak", C7, "") | G7: =IF(E7="4-Day Down Streak", IF(F7>0, "Yes", "No"), "") | K7: Count of 4-Day Down | L7: =COUNTIF(E:E, "4-Day Down STreak") -> 79
A8: 43948 | B8: 9282.3 | C8: =(B8-B7)/B7 -> 0.013971424 | D8: =IF(C8>0, "Up", IF(C8<0, "Down", "Flat")) -> Up | E8: =IF(AND(D4="Down", D5="Down", D6="Down", D7="Down"), "4-Day Down Streak", "") | F8: =IF(E8="4-Day Down Streak", C8, "") | G8: =IF(E8="4-Day Down Streak", IF(F8>0, "Yes", "No"), "") | K8: Count of 5th Day up | L8: =COUNTIF(G:G, "Yes") -> 34
A9: 43949 | B9: 9380.9 | C9: =(B9-B8)/B8 -> 0.010622367 | D9: =IF(C9>0, "Up", IF(C9<0, "Down", "Flat")) -> Up | E9: =IF(AND(D5="Down", D6="Down", D7="Down", D8="Down"), "4-Day Down Streak", "") | F9: =IF(E9="4-Day Down Streak", C9, "") | G9: =IF(E9="4-Day Down Streak", IF(F9>0, "Yes", "No"), "") | K9: % of times | L9: =L8/L7 -> 0.43037975
A10: 43950 | B10: 9553.35 | C10: =(B10-B9)/B9 -> 0.018383098 | D10: =IF(C10>0, "Up", IF(C10<0, "Down", "Flat")) -> Up | E10: =IF(AND(D6="Down", D7="Down", D8="Down", D9="Down"), "4-Day Down Streak", "") | F10: =IF(E10="4-Day Down Streak", C10, "") | G10: =IF(E10="4-Day Down Streak", IF(F10>0, "Yes", "No"), "") | K10: Average Return on 5th Day (When Up) | L10: =AVERAGEIFS(F:F, G:G, "Yes") -> 0.0092038209
A11: 43951 | B11: 9859.9 | C11: =(B11-B10)/B10 -> 0.03208822 | D11: =IF(C11>0, "Up", IF(C11<0, "Down", "Flat")) -> Up | E11: =IF(AND(D7="Down", D8="Down", D9="Down", D10="Down"), "4-Day Down Streak", "") | F11: =IF(E11="4-Day Down Streak", C11, "") | G11: =IF(E11="4-Day Down Streak", IF(F11>0, "Yes", "No"), "") | K11: Average Return on All 5th Days (Even if Down) | L11: =AVERAGEIF(E:E, "4-Day Down Streak", F:F) -> -0.0011771837
A12: 43955 | B12: 9293.5 | C12: =(B12-B11)/B11 -> -0.057444802 | D12: =IF(C12>0, "Up", IF(C12<0, "Down", "Flat")) -> Down | E12: =IF(AND(D8="Down", D9="Down", D10="Down", D11="Down"), "4-Day Down Streak", "") | F12: =IF(E12="4-Day Down Streak", C12, "") | G12: =IF(E12="4-Day Down Streak", IF(F12>0, "Yes", "No"), "")
A13: 43956 | B13: 9205.6 | C13: =(B13-B12)/B12 -> -0.0094582235 | D13: =IF(C13>0, "Up", IF(C13<0, "Down", "Flat")) -> Down | E13: =IF(AND(D9="Down", D10="Down", D11="Down", D12="Down"), "4-Day Down Streak", "") | F13: =IF(E13="4-Day Down Streak", C13, "") | G13: =IF(E13="4-Day Down Streak", IF(F13>0, "Yes", "No"), "") | K13: Up | L13: =COUNTIF(G:G, "Yes") -> 34
A14: 43957 | B14: 9270.9 | C14: =(B14-B13)/B13 -> 0.0070935083 | D14: =IF(C14>0, "Up", IF(C14<0, "Down", "Flat")) -> Up | E14: =IF(AND(D10="Down", D11="Down", D12="Down", D13="Down"), "4-Day Down Streak", "") | F14: =IF(E14="4-Day Down Streak", C14, "") | G14: =IF(E14="4-Day Down Streak", IF(F14>0, "Yes", "No"), "") | K14: Down | L14: =COUNTIF(G:G, "No") -> 44
A15: 43958 | B15: 9199.05 | C15: =(B15-B14)/B14 -> -0.0077500566 | D15: =IF(C15>0, "Up", IF(C15<0, "Down", "Flat")) -> Down | E15: =IF(AND(D11="Down", D12="Down", D13="Down", D14="Down"), "4-Day Down Streak", "") | F15: =IF(E15="4-Day Down Streak", C15, "") | G15: =IF(E15="4-Day Down Streak", IF(F15>0, "Yes", "No"), "")
A16: 43959 | B16: 9251.5 | C16: =(B16-B15)/B15 -> 0.0057016757 | D16: =IF(C16>0, "Up", IF(C16<0, "Down", "Flat")) -> Up | E16: =IF(AND(D12="Down", D13="Down", D14="Down", D15="Down"), "4-Day Down Streak", "") | F16: =IF(E16="4-Day Down Streak", C16, "") | G16: =IF(E16="4-Day Down Streak", IF(F16>0, "Yes", "No"), "")
A17: 43962 | B17: 9239.2 | C17: =(B17-B16)/B16 -> -0.0013295141 | D17: =IF(C17>0, "Up", IF(C17<0, "Down", "Flat")) -> Down | E17: =IF(AND(D13="Down", D14="Down", D15="Down", D16="Down"), "4-Day Down Streak", "") | F17: =IF(E17="4-Day Down Streak", C17, "") | G17: =IF(E17="4-Day Down Streak", IF(F17>0, "Yes", "No"), "")
A18: 43963 | B18: 9196.55 | C18: =(B18-B17)/B17 -> -0.0046162005 | D18: =IF(C18>0, "Up", IF(C18<0, "Down", "Flat")) -> Down | E18: =IF(AND(D14="Down", D15="Down", D16="Down", D17="Down"), "4-Day Down Streak", "") | F18: =IF(E18="4-Day Down Streak", C18, "") | G18: =IF(E18="4-Day Down Streak", IF(F18>0, "Yes", "No"), "")
A19: 43964 | B19: 9383.55 | C19: =(B19-B18)/B18 -> 0.020333712 | D19: =IF(C19>0, "Up", IF(C19<0, "Down", "Flat")) -> Up | E19: =IF(AND(D15="Down", D16="Down", D17="Down", D18="Down"), "4-Day Down Streak", "") | F19: =IF(E19="4-Day Down Streak", C19, "") | G19: =IF(E19="4-Day Down Streak", IF(F19>0, "Yes", "No"), "")
A20: 43965 | B20: 9142.75 | C20: =(B20-B19)/B19 -> -0.02566193 | D20: =IF(C20>0, "Up", IF(C20<0, "Down", "Flat")) -> Down | E20: =IF(AND(D16="Down", D17="Down", D18="Down", D19="Down"), "4-Day Down Streak", "") | F20: =IF(E20="4-Day Down Streak", C20, "") | G20: =IF(E20="4-Day Down Streak", IF(F20>0, "Yes", "No"), "")
A21: 43966 | B21: 9136.85 | C21: =(B21-B20)/B20 -> -0.00064532006 | D21: =IF(C21>0, "Up", IF(C21<0, "Down", "Flat")) -> Down | E21: =IF(AND(D17="Down", D18="Down", D19="Down", D20="Down"), "4-Day Down Streak", "") | F21: =IF(E21="4-Day Down Streak", C21, "") | G21: =IF(E21="4-Day Down Streak", IF(F21>0, "Yes", "No"), "")
A22: 43969 | B22: 8823.25 | C22: =(B22-B21)/B21 -> -0.034322551 | D22: =IF(C22>0, "Up", IF(C22<0, "Down", "Flat")) -> Down | E22: =IF(AND(D18="Down", D19="Down", D20="Down", D21="Down"), "4-Day Down Streak", "") | F22: =IF(E22="4-Day Down Streak", C22, "") | G22: =IF(E22="4-Day Down Streak", IF(F22>0, "Yes", "No"), "")
A23: 43970 | B23: 8879.1 | C23: =(B23-B22)/B22 -> 0.0063298671 | D23: =IF(C23>0, "Up", IF(C23<0, "Down", "Flat")) -> Up | E23: =IF(AND(D19="Down", D20="Down", D21="Down", D22="Down"), "4-Day Down Streak", "") | F23: =IF(E23="4-Day Down Streak", C23, "") | G23: =IF(E23="4-Day Down Streak", IF(F23>0, "Yes", "No"), "")
A24: 43971 | B24: 9066.55 | C24: =(B24-B23)/B23 -> 0.021111374 | D24: =IF(C24>0, "Up", IF(C24<0, "Down", "Flat")) -> Up | E24: =IF(AND(D20="Down", D21="Down", D22="Down", D23="Down"), "4-Day Down Streak", "") | F24: =IF(E24="4-Day Down Streak", C24, "") | G24: =IF(E24="4-Day Down Streak", IF(F24>0, "Yes", "No"), "")
A25: 43972 | B25: 9106.25 | C25: =(B25-B24)/B24 -> 0.0043787328 | D25: =IF(C25>0, "Up", IF(C25<0, "Down", "Flat")) -> Up | E25: =IF(AND(D21="Down", D22="Down", D23="Down", D24="Down"), "4-Day Down Streak", "") | F25: =IF(E25="4-Day Down Streak", C25, "") | G25: =IF(E25="4-Day Down Streak", IF(F25>0, "Yes", "No"), "")
A26: 43973 | B26: 9039.25 | C26: =(B26-B25)/B25 -> -0.0073575841 | D26: =IF(C26>0, "Up", IF(C26<0, "Down", "Flat")) -> Down | E26: =IF(AND(D22="Down", D23="Down", D24="Down", D25="Down"), "4-Day Down Streak", "") | F26: =IF(E26="4-Day Down Streak", C26, "") | G26: =IF(E26="4-Day Down Streak", IF(F26>0, "Yes", "No"), "")
... A1245: 45764 | B1245: 23851.65 | C1245: =(B1245-B1244)/B1244 -> 0.017683426 | D1245: =IF(C1245>0, "Up", IF(C1245<0, "Down", "Flat")) -> Up | E1245: =IF(AND(D1241="Down", D1242="Down", D1243="Down", D1244="Down"), "4-Day Down Streak", "") | F1245: =IF(E1245="4-Day Down Streak", C1245, "") | G1245: =IF(E1245="4-Day Down Streak", IF(F1245>0, "Yes", "No"), "")

Sheet 6th Day Trading Pattern
A1: Date | B1: Close | C1: Daily Returns | D1: Up/Down | E1: 5-Day Down Streak | F1: 6th Day Return | G1: Was 6th Day Up?
A2: 43938 | B2: 9266.75 | F2: =IF(E2="5-Day Down Streak", C2, "") | G2: =IF(E2="5-Day Down Streak", IF(F2>0, "Yes", "No"), "")
A3: 43941 | B3: 9261.85 | C3: =(B3-B2)/B2 -> -0.00052877222 | D3: =IF(C3>0, "Up", IF(C3<0, "Down", "Flat")) -> Down | F3: =IF(E3="5-Day Down Streak", C3, "") | G3: =IF(E3="5-Day Down Streak", IF(F3>0, "Yes", "No"), "")
A4: 43942 | B4: 8981.45 | C4: =(B4-B3)/B3 -> -0.030274729 | D4: =IF(C4>0, "Up", IF(C4<0, "Down", "Flat")) -> Down | F4: =IF(E4="5-Day Down Streak", C4, "") | G4: =IF(E4="5-Day Down Streak", IF(F4>0, "Yes", "No"), "")
A5: 43943 | B5: 9187.3 | C5: =(B5-B4)/B4 -> 0.022919462 | D5: =IF(C5>0, "Up", IF(C5<0, "Down", "Flat")) -> Up | F5: =IF(E5="5-Day Down Streak", C5, "") | G5: =IF(E5="5-Day Down Streak", IF(F5>0, "Yes", "No"), "")
A6: 43944 | B6: 9313.9 | C6: =(B6-B5)/B5 -> 0.013779892 | D6: =IF(C6>0, "Up", IF(C6<0, "Down", "Flat")) -> Up | F6: =IF(E6="5-Day Down Streak", C6, "") | G6: =IF(E6="5-Day Down Streak", IF(F6>0, "Yes", "No"), "")
A7: 43945 | B7: 9154.4 | C7: =(B7-B6)/B6 -> -0.017124942 | D7: =IF(C7>0, "Up", IF(C7<0, "Down", "Flat")) -> Down | E7: =IF(AND(D2="Down", D3="Down", D4="Down", D5="Down", D6="Down"), "5-Day Down Streak", "") | F7: =IF(E7="5-Day Down Streak", C7, "") | G7: =IF(E7="5-Day Down Streak", IF(F7>0, "Yes", "No"), "") | M7: Count of 5-Day Down | N7: =COUNTIF(E:E, "5-Day Down STreak") -> 45
A8: 43948 | B8: 9282.3 | C8: =(B8-B7)/B7 -> 0.013971424 | D8: =IF(C8>0, "Up", IF(C8<0, "Down", "Flat")) -> Up | E8: =IF(AND(D3="Down", D4="Down", D5="Down", D6="Down", D7="Down"), "5-Day Down Streak", "") | F8: =IF(E8="5-Day Down Streak", C8, "") | G8: =IF(E8="5-Day Down Streak", IF(F8>0, "Yes", "No"), "") | M8: Count of 6th Day up | N8: =COUNTIF(G:G, "Yes") -> 21
A9: 43949 | B9: 9380.9 | C9: =(B9-B8)/B8 -> 0.010622367 | D9: =IF(C9>0, "Up", IF(C9<0, "Down", "Flat")) -> Up | E9: =IF(AND(D4="Down", D5="Down", D6="Down", D7="Down", D8="Down"), "5-Day Down Streak", "") | F9: =IF(E9="5-Day Down Streak", C9, "") | G9: =IF(E9="5-Day Down Streak", IF(F9>0, "Yes", "No"), "") | M9: % of times | N9: =N8/N7 -> 0.46666667
A10: 43950 | B10: 9553.35 | C10: =(B10-B9)/B9 -> 0.018383098 | D10: =IF(C10>0, "Up", IF(C10<0, "Down", "Flat")) -> Up | E10: =IF(AND(D5="Down", D6="Down", D7="Down", D8="Down", D9="Down"), "5-Day Down Streak", "") | F10: =IF(E10="5-Day Down Streak", C10, "") | G10: =IF(E10="5-Day Down Streak", IF(F10>0, "Yes", "No"), "") | M10: Average Return on 6th Day (When Up) | N10: =AVERAGEIFS(F:F, G:G, "Yes") -> 0.010905188
A11: 43951 | B11: 9859.9 | C11: =(B11-B10)/B10 -> 0.03208822 | D11: =IF(C11>0, "Up", IF(C11<0, "Down", "Flat")) -> Up | E11: =IF(AND(D6="Down", D7="Down", D8="Down", D9="Down", D10="Down"), "5-Day Down Streak", "") | F11: =IF(E11="5-Day Down Streak", C11, "") | G11: =IF(E11="5-Day Down Streak", IF(F11>0, "Yes", "No"), "") | M11: Average Return on All 6th Days (Even if Down) | N11: =AVERAGEIF(E:E, "5-Day Down Streak", F:F) -> 0.0012220179
A12: 43955 | B12: 9293.5 | C12: =(B12-B11)/B11 -> -0.057444802 | D12: =IF(C12>0, "Up", IF(C12<0, "Down", "Flat")) -> Down | E12: =IF(AND(D7="Down", D8="Down", D9="Down", D10="Down", D11="Down"), "5-Day Down Streak", "") | F12: =IF(E12="5-Day Down Streak", C12, "") | G12: =IF(E12="5-Day Down Streak", IF(F12>0, "Yes", "No"), "")
A13: 43956 | B13: 9205.6 | C13: =(B13-B12)/B12 -> -0.0094582235 | D13: =IF(C13>0, "Up", IF(C13<0, "Down", "Flat")) -> Down | E13: =IF(AND(D8="Down", D9="Down", D10="Down", D11="Down", D12="Down"), "5-Day Down Streak", "") | F13: =IF(E13="5-Day Down Streak", C13, "") | G13: =IF(E13="5-Day Down Streak", IF(F13>0, "Yes", "No"), "") | M13: Up | N13: =COUNTIF(G:G, "Yes") -> 21
A14: 43957 | B14: 9270.9 | C14: =(B14-B13)/B13 -> 0.0070935083 | D14: =IF(C14>0, "Up", IF(C14<0, "Down", "Flat")) -> Up | E14: =IF(AND(D9="Down", D10="Down", D11="Down", D12="Down", D13="Down"), "5-Day Down Streak", "") | F14: =IF(E14="5-Day Down Streak", C14, "") | G14: =IF(E14="5-Day Down Streak", IF(F14>0, "Yes", "No"), "") | M14: Down | N14: =COUNTIF(G:G, "No") -> 23
A15: 43958 | B15: 9199.05 | C15: =(B15-B14)/B14 -> -0.0077500566 | D15: =IF(C15>0, "Up", IF(C15<0, "Down", "Flat")) -> Down | E15: =IF(AND(D10="Down", D11="Down", D12="Down", D13="Down", D14="Down"), "5-Day Down Streak", "") | F15: =IF(E15="5-Day Down Streak", C15, "") | G15: =IF(E15="5-Day Down Streak", IF(F15>0, "Yes", "No"), "")
A16: 43959 | B16: 9251.5 | C16: =(B16-B15)/B15 -> 0.0057016757 | D16: =IF(C16>0, "Up", IF(C16<0, "Down", "Flat")) -> Up | E16: =IF(AND(D11="Down", D12="Down", D13="Down", D14="Down", D15="Down"), "5-Day Down Streak", "") | F16: =IF(E16="5-Day Down Streak", C16, "") | G16: =IF(E16="5-Day Down Streak", IF(F16>0, "Yes", "No"), "")
A17: 43962 | B17: 9239.2 | C17: =(B17-B16)/B16 -> -0.0013295141 | D17: =IF(C17>0, "Up", IF(C17<0, "Down", "Flat")) -> Down | E17: =IF(AND(D12="Down", D13="Down", D14="Down", D15="Down", D16="Down"), "5-Day Down Streak", "") | F17: =IF(E17="5-Day Down Streak", C17, "") | G17: =IF(E17="5-Day Down Streak", IF(F17>0, "Yes", "No"), "")
A18: 43963 | B18: 9196.55 | C18: =(B18-B17)/B17 -> -0.0046162005 | D18: =IF(C18>0, "Up", IF(C18<0, "Down", "Flat")) -> Down | E18: =IF(AND(D13="Down", D14="Down", D15="Down", D16="Down", D17="Down"), "5-Day Down Streak", "") | F18: =IF(E18="5-Day Down Streak", C18, "") | G18: =IF(E18="5-Day Down Streak", IF(F18>0, "Yes", "No"), "")
A19: 43964 | B19: 9383.55 | C19: =(B19-B18)/B18 -> 0.020333712 | D19: =IF(C19>0, "Up", IF(C19<0, "Down", "Flat")) -> Up | E19: =IF(AND(D14="Down", D15="Down", D16="Down", D17="Down", D18="Down"), "5-Day Down Streak", "") | F19: =IF(E19="5-Day Down Streak", C19, "") | G19: =IF(E19="5-Day Down Streak", IF(F19>0, "Yes", "No"), "")
A20: 43965 | B20: 9142.75 | C20: =(B20-B19)/B19 -> -0.02566193 | D20: =IF(C20>0, "Up", IF(C20<0, "Down", "Flat")) -> Down | E20: =IF(AND(D15="Down", D16="Down", D17="Down", D18="Down", D19="Down"), "5-Day Down Streak", "") | F20: =IF(E20="5-Day Down Streak", C20, "") | G20: =IF(E20="5-Day Down Streak", IF(F20>0, "Yes", "No"), "")
A21: 43966 | B21: 9136.85 | C21: =(B21-B20)/B20 -> -0.00064532006 | D21: =IF(C21>0, "Up", IF(C21<0, "Down", "Flat")) -> Down | E21: =IF(AND(D16="Down", D17="Down", D18="Down", D19="Down", D20="Down"), "5-Day Down Streak", "") | F21: =IF(E21="5-Day Down Streak", C21, "") | G21: =IF(E21="5-Day Down Streak", IF(F21>0, "Yes", "No"), "")
A22: 43969 | B22: 8823.25 | C22: =(B22-B21)/B21 -> -0.034322551 | D22: =IF(C22>0, "Up", IF(C22<0, "Down", "Flat")) -> Down | E22: =IF(AND(D17="Down", D18="Down", D19="Down", D20="Down", D21="Down"), "5-Day Down Streak", "") | F22: =IF(E22="5-Day Down Streak", C22, "") | G22: =IF(E22="5-Day Down Streak", IF(F22>0, "Yes", "No"), "")
A23: 43970 | B23: 8879.1 | C23: =(B23-B22)/B22 -> 0.0063298671 | D23: =IF(C23>0, "Up", IF(C23<0, "Down", "Flat")) -> Up | E23: =IF(AND(D18="Down", D19="Down", D20="Down", D21="Down", D22="Down"), "5-Day Down Streak", "") | F23: =IF(E23="5-Day Down Streak", C23, "") | G23: =IF(E23="5-Day Down Streak", IF(F23>0, "Yes", "No"), "")
A24: 43971 | B24: 9066.55 | C24: =(B24-B23)/B23 -> 0.021111374 | D24: =IF(C24>0, "Up", IF(C24<0, "Down", "Flat")) -> Up | E24: =IF(AND(D19="Down", D20="Down", D21="Down", D22="Down", D23="Down"), "5-Day Down Streak", "") | F24: =IF(E24="5-Day Down Streak", C24, "") | G24: =IF(E24="5-Day Down Streak", IF(F24>0, "Yes", "No"), "")
A25: 43972 | B25: 9106.25 | C25: =(B25-B24)/B24 -> 0.0043787328 | D25: =IF(C25>0, "Up", IF(C25<0, "Down", "Flat")) -> Up | E25: =IF(AND(D20="Down", D21="Down", D22="Down", D23="Down", D24="Down"), "5-Day Down Streak", "") | F25: =IF(E25="5-Day Down Streak", C25, "") | G25: =IF(E25="5-Day Down Streak", IF(F25>0, "Yes", "No"), "")
A26: 43973 | B26: 9039.25 | C26: =(B26-B25)/B25 -> -0.0073575841 | D26: =IF(C26>0, "Up", IF(C26<0, "Down", "Flat")) -> Down | E26: =IF(AND(D21="Down", D22="Down", D23="Down", D24="Down", D25="Down"), "5-Day Down Streak", "") | F26: =IF(E26="5-Day Down Streak", C26, "") | G26: =IF(E26="5-Day Down Streak", IF(F26>0, "Yes", "No"), "")
... A1245: 45764 | B1245: 23851.65 | C1245: =(B1245-B1244)/B1244 -> 0.017683426 | D1245: =IF(C1245>0, "Up", IF(C1245<0, "Down", "Flat")) -> Up | E1245: =IF(AND(D1240="Down", D1241="Down", D1242="Down", D1243="Down", D1244="Down"), "5-Day Down Streak", "") | F1245: =IF(E1245="5-Day Down Streak", C1245, "") | G1245: =IF(E1245="5-Day Down Streak", IF(F1245>0, "Yes", "No"), "")

Sheet 7th Day Trading Pattern
A1: Date | B1: Close | C1: Daily Returns | D1: Up/Down | E1: 6-Day Down Streak | F1: 7th Day Return | G1: Was 7th Day Up?
A2: 43938 | B2: 9266.75 | F2: =IF(E2="6-Day Down Streak", C2, "") | G2: =IF(E2="6-Day Down Streak", IF(F2>0, "Yes", "No"), "")
A3: 43941 | B3: 9261.85 | C3: =(B3-B2)/B2 -> -0.00052877222 | D3: =IF(C3>0, "Up", IF(C3<0, "Down", "Flat")) -> Down | F3: =IF(E3="6-Day Down Streak", C3, "") | G3: =IF(E3="6-Day Down Streak", IF(F3>0, "Yes", "No"), "")
A4: 43942 | B4: 8981.45 | C4: =(B4-B3)/B3 -> -0.030274729 | D4: =IF(C4>0, "Up", IF(C4<0, "Down", "Flat")) -> Down | F4: =IF(E4="6-Day Down Streak", C4, "") | G4: =IF(E4="6-Day Down Streak", IF(F4>0, "Yes", "No"), "")
A5: 43943 | B5: 9187.3 | C5: =(B5-B4)/B4 -> 0.022919462 | D5: =IF(C5>0, "Up", IF(C5<0, "Down", "Flat")) -> Up | F5: =IF(E5="6-Day Down Streak", C5, "") | G5: =IF(E5="6-Day Down Streak", IF(F5>0, "Yes", "No"), "")
A6: 43944 | B6: 9313.9 | C6: =(B6-B5)/B5 -> 0.013779892 | D6: =IF(C6>0, "Up", IF(C6<0, "Down", "Flat")) -> Up | F6: =IF(E6="6-Day Down Streak", C6, "") | G6: =IF(E6="6-Day Down Streak", IF(F6>0, "Yes", "No"), "")
A7: 43945 | B7: 9154.4 | C7: =(B7-B6)/B6 -> -0.017124942 | D7: =IF(C7>0, "Up", IF(C7<0, "Down", "Flat")) -> Down | F7: =IF(E7="6-Day Down Streak", C7, "") | G7: =IF(E7="6-Day Down Streak", IF(F7>0, "Yes", "No"), "")
A8: 43948 | B8: 9282.3 | C8: =(B8-B7)/B7 -> 0.013971424 | D8: =IF(C8>0, "Up", IF(C8<0, "Down", "Flat")) -> Up | F8: =IF(E8="6-Day Down Streak", C8, "") | G8: =IF(E8="6-Day Down Streak", IF(F8>0, "Yes", "No"), "") | L8: Count of 6-Day Down | M8: =COUNTIF(E:E, "6-Day Down STreak") -> 24
A9: 43949 | B9: 9380.9 | C9: =(B9-B8)/B8 -> 0.010622367 | D9: =IF(C9>0, "Up", IF(C9<0, "Down", "Flat")) -> Up | E9: =IF(AND(D3="Down", D4="Down", D5="Down", D6="Down", D7="Down", D8="Down"), "6-Day Down Streak", "") | F9: =IF(E9="6-Day Down Streak", C9, "") | G9: =IF(E9="6-Day Down Streak", IF(F9>0, "Yes", "No"), "") | L9: Count of 7th Day up | M9: =COUNTIF(G:G, "Yes") -> 12
A10: 43950 | B10: 9553.35 | C10: =(B10-B9)/B9 -> 0.018383098 | D10: =IF(C10>0, "Up", IF(C10<0, "Down", "Flat")) -> Up | E10: =IF(AND(D4="Down", D5="Down", D6="Down", D7="Down", D8="Down", D9="Down"), "6-Day Down Streak", "") | F10: =IF(E10="6-Day Down Streak", C10, "") | G10: =IF(E10="6-Day Down Streak", IF(F10>0, "Yes", "No"), "") | L10: % of times | M10: =M9/M8 -> 0.5
A11: 43951 | B11: 9859.9 | C11: =(B11-B10)/B10 -> 0.03208822 | D11: =IF(C11>0, "Up", IF(C11<0, "Down", "Flat")) -> Up | E11: =IF(AND(D5="Down", D6="Down", D7="Down", D8="Down", D9="Down", D10="Down"), "6-Day Down Streak", "") | F11: =IF(E11="6-Day Down Streak", C11, "") | G11: =IF(E11="6-Day Down Streak", IF(F11>0, "Yes", "No"), "") | L11: Average Return on 7th Day (When Up) | M11: =AVERAGEIFS(F:F, G:G, "Yes") -> 0.013518106
A12: 43955 | B12: 9293.5 | C12: =(B12-B11)/B11 -> -0.057444802 | D12: =IF(C12>0, "Up", IF(C12<0, "Down", "Flat")) -> Down | E12: =IF(AND(D6="Down", D7="Down", D8="Down", D9="Down", D10="Down", D11="Down"), "6-Day Down Streak", "") | F12: =IF(E12="6-Day Down Streak", C12, "") | G12: =IF(E12="6-Day Down Streak", IF(F12>0, "Yes", "No"), "") | L12: Average Return on All 7th Days (Even if Down) | M12: =AVERAGEIF(E:E, "6-Day Down Streak", F:F) -> 0.0032043509
A13: 43956 | B13: 9205.6 | C13: =(B13-B12)/B12 -> -0.0094582235 | D13: =IF(C13>0, "Up", IF(C13<0, "Down", "Flat")) -> Down | E13: =IF(AND(D7="Down", D8="Down", D9="Down", D10="Down", D11="Down", D12="Down"), "6-Day Down Streak", "") | F13: =IF(E13="6-Day Down Streak", C13, "") | G13: =IF(E13="6-Day Down Streak", IF(F13>0, "Yes", "No"), "")
A14: 43957 | B14: 9270.9 | C14: =(B14-B13)/B13 -> 0.0070935083 | D14: =IF(C14>0, "Up", IF(C14<0, "Down", "Flat")) -> Up | E14: =IF(AND(D8="Down", D9="Down", D10="Down", D11="Down", D12="Down", D13="Down"), "6-Day Down Streak", "") | F14: =IF(E14="6-Day Down Streak", C14, "") | G14: =IF(E14="6-Day Down Streak", IF(F14>0, "Yes", "No"), "") | L14: Up | M14: =COUNTIF(G:G, "Yes") -> 12
A15: 43958 | B15: 9199.05 | C15: =(B15-B14)/B14 -> -0.0077500566 | D15: =IF(C15>0, "Up", IF(C15<0, "Down", "Flat")) -> Down | E15: =IF(AND(D9="Down", D10="Down", D11="Down", D12="Down", D13="Down", D14="Down"), "6-Day Down Streak", "") | F15: =IF(E15="6-Day Down Streak", C15, "") | G15: =IF(E15="6-Day Down Streak", IF(F15>0, "Yes", "No"), "") | L15: Down | M15: =COUNTIF(G:G, "No") -> 11
A16: 43959 | B16: 9251.5 | C16: =(B16-B15)/B15 -> 0.0057016757 | D16: =IF(C16>0, "Up", IF(C16<0, "Down", "Flat")) -> Up | E16: =IF(AND(D10="Down", D11="Down", D12="Down", D13="Down", D14="Down", D15="Down"), "6-Day Down Streak", "") | F16: =IF(E16="6-Day Down Streak", C16, "") | G16: =IF(E16="6-Day Down Streak", IF(F16>0, "Yes", "No"), "")
A17: 43962 | B17: 9239.2 | C17: =(B17-B16)/B16 -> -0.0013295141 | D17: =IF(C17>0, "Up", IF(C17<0, "Down", "Flat")) -> Down | E17: =IF(AND(D11="Down", D12="Down", D13="Down", D14="Down", D15="Down", D16="Down"), "6-Day Down Streak", "") | F17: =IF(E17="6-Day Down Streak", C17, "") | G17: =IF(E17="6-Day Down Streak", IF(F17>0, "Yes", "No"), "")
A18: 43963 | B18: 9196.55 | C18: =(B18-B17)/B17 -> -0.0046162005 | D18: =IF(C18>0, "Up", IF(C18<0, "Down", "Flat")) -> Down | E18: =IF(AND(D12="Down", D13="Down", D14="Down", D15="Down", D16="Down", D17="Down"), "6-Day Down Streak", "") | F18: =IF(E18="6-Day Down Streak", C18, "") | G18: =IF(E18="6-Day Down Streak", IF(F18>0, "Yes", "No"), "")
A19: 43964 | B19: 9383.55 | C19: =(B19-B18)/B18 -> 0.020333712 | D19: =IF(C19>0, "Up", IF(C19<0, "Down", "Flat")) -> Up | E19: =IF(AND(D13="Down", D14="Down", D15="Down", D16="Down", D17="Down", D18="Down"), "6-Day Down Streak", "") | F19: =IF(E19="6-Day Down Streak", C19, "") | G19: =IF(E19="6-Day Down Streak", IF(F19>0, "Yes", "No"), "")
A20: 43965 | B20: 9142.75 | C20: =(B20-B19)/B19 -> -0.02566193 | D20: =IF(C20>0, "Up", IF(C20<0, "Down", "Flat")) -> Down | E20: =IF(AND(D14="Down", D15="Down", D16="Down", D17="Down", D18="Down", D19="Down"), "6-Day Down Streak", "") | F20: =IF(E20="6-Day Down Streak", C20, "") | G20: =IF(E20="6-Day Down Streak", IF(F20>0, "Yes", "No"), "")
A21: 43966 | B21: 9136.85 | C21: =(B21-B20)/B20 -> -0.00064532006 | D21: =IF(C21>0, "Up", IF(C21<0, "Down", "Flat")) -> Down | E21: =IF(AND(D15="Down", D16="Down", D17="Down", D18="Down", D19="Down", D20="Down"), "6-Day Down Streak", "") | F21: =IF(E21="6-Day Down Streak", C21, "") | G21: =IF(E21="6-Day Down Streak", IF(F21>0, "Yes", "No"), "")
A22: 43969 | B22: 8823.25 | C22: =(B22-B21)/B21 -> -0.034322551 | D22: =IF(C22>0, "Up", IF(C22<0, "Down", "Flat")) -> Down | E22: =IF(AND(D16="Down", D17="Down", D18="Down", D19="Down", D20="Down", D21="Down"), "6-Day Down Streak", "") | F22: =IF(E22="6-Day Down Streak", C22, "") | G22: =IF(E22="6-Day Down Streak", IF(F22>0, "Yes", "No"), "")
A23: 43970 | B23: 8879.1 | C23: =(B23-B22)/B22 -> 0.0063298671 | D23: =IF(C23>0, "Up", IF(C23<0, "Down", "Flat")) -> Up | E23: =IF(AND(D17="Down", D18="Down", D19="Down", D20="Down", D21="Down", D22="Down"), "6-Day Down Streak", "") | F23: =IF(E23="6-Day Down Streak", C23, "") | G23: =IF(E23="6-Day Down Streak", IF(F23>0, "Yes", "No"), "")
A24: 43971 | B24: 9066.55 | C24: =(B24-B23)/B23 -> 0.021111374 | D24: =IF(C24>0, "Up", IF(C24<0, "Down", "Flat")) -> Up | E24: =IF(AND(D18="Down", D19="Down", D20="Down", D21="Down", D22="Down", D23="Down"), "6-Day Down Streak", "") | F24: =IF(E24="6-Day Down Streak", C24, "") | G24: =IF(E24="6-Day Down Streak", IF(F24>0, "Yes", "No"), "")
